{"uuid": "80ee6d20-e669-428d-8d9c-6814e96f01e5", "children": ["cb79e84f-2eba-444a-9cd7-a962e7a835ac"], "befores": [{"name": "app", "status": "broken", "statusDetails": {"message": "selenium.common.exceptions.WebDriverException: Message: 'chromedriver 2' executable needs to be in PATH. Please see https://sites.google.com/a/chromium.org/chromedriver/home\n\n", "trace": "  File \"/usr/local/lib/python3.7/site-packages/pluggy/callers.py\", line 187, in _multicall\n    res = hook_impl.function(*args)\n  File \"/usr/local/lib/python3.7/site-packages/_pytest/fixtures.py\", line 923, in pytest_fixture_setup\n    result = call_fixture_func(fixturefunc, request, kwargs)\n  File \"/usr/local/lib/python3.7/site-packages/_pytest/fixtures.py\", line 783, in call_fixture_func\n    res = fixturefunc(**kwargs)\n  File \"/Users/arm/demobcd/conftest.py\", line 35, in app\n    fixture = Application()\n  File \"/Users/arm/demobcd/fixture/application.py\", line 19, in __init__\n    self.wd = WebDriver(executable_path='../drivers/chromedriver 2')\n  File \"/usr/local/lib/python3.7/site-packages/selenium/webdriver/chrome/webdriver.py\", line 73, in __init__\n    self.service.start()\n  File \"/usr/local/lib/python3.7/site-packages/selenium/webdriver/common/service.py\", line 83, in start\n    os.path.basename(self.path), self.start_error_message)\n"}, "start": 1564478796325, "stop": 1564478796369}], "start": 1564478796325, "stop": 1564478796516}