{"uuid": "32363c79-4652-411b-afd0-dad25c3552fe", "children": ["0ec4b77e-2f2d-4758-9b91-2dfb2990dfba"], "befores": [{"name": "app", "status": "broken", "statusDetails": {"message": "selenium.common.exceptions.WebDriverException: Message: 'chromedriver 2' executable needs to be in PATH. Please see https://sites.google.com/a/chromium.org/chromedriver/home\n\n", "trace": "  File \"/usr/local/lib/python3.7/site-packages/pluggy/callers.py\", line 187, in _multicall\n    res = hook_impl.function(*args)\n  File \"/usr/local/lib/python3.7/site-packages/_pytest/fixtures.py\", line 923, in pytest_fixture_setup\n    result = call_fixture_func(fixturefunc, request, kwargs)\n  File \"/usr/local/lib/python3.7/site-packages/_pytest/fixtures.py\", line 783, in call_fixture_func\n    res = fixturefunc(**kwargs)\n  File \"/Users/arm/demobcd/conftest.py\", line 35, in app\n    fixture = Application()\n  File \"/Users/arm/demobcd/fixture/application.py\", line 19, in __init__\n    self.wd = WebDriver(executable_path='/demobcd/drivers/chromedriver 2')\n  File \"/usr/local/lib/python3.7/site-packages/selenium/webdriver/chrome/webdriver.py\", line 73, in __init__\n    self.service.start()\n  File \"/usr/local/lib/python3.7/site-packages/selenium/webdriver/common/service.py\", line 83, in start\n    os.path.basename(self.path), self.start_error_message)\n"}, "start": 1564479085601, "stop": 1564479085642}], "start": 1564479085601, "stop": 1564479085788}